Workbook

Sheet Prospects
A1: Perko - Local Business Prospects, Jerusalem (Emek Refaim & Derech Beit Lehem)
A2: Research list for the Perko early-access pilot. 20 businesses. Prospects only: none has agreed to participate. Contact details are public business details as published; blanks mean not verified.
A3: Business Name (Hebrew) | B3: English Name | C3: Business Category | D3: Street | E3: Full Address | F3: Public Business Phone | G3: Public Business Email | H3: Official Website | I3: Instagram Profile | J3: Other Relevant Social Profile | K3: Contact Person | L3: Contact Person's Role | M3: Business Description | N3: Why This Business Fits Perko | O3: Repeat-Customer Potential | P3: Perko Fit Score (1-10) | Q3: Independence Status | R3: Best Public Contact Method | S3: Source URL - Business Details | T3: Source URL - Contact Information | U3: Date Verified | V3: Outreach Status | W3: Additional Notes | X3: Suggested Outreach Message (Hebrew)
A4: בירמה | B4: Birma Coffee | C4: Café / coffee roaster | D4: Emek Refaim | E4: 20 Emek Refaim St, German Colony, Jerusalem | F4: 02-544-5668 | H4: https://birmacoffee.com | I4: https://www.instagram.com/birmacoffee | J4: https://www.facebook.com/birmacoffee | K4: Michael Ronen; Daniel Ronen | L4: Co-founders / owners (brothers) | M4: Small specialty-coffee micro-roastery and counter café opened in 2021, with outdoor seating. Kosher. | N4: A takeaway counter with commuter regulars is the textbook stamp-card business, and a young founder-run brand is likely to try a digital card in place of paper. Its coffee-bean sales add a second repeat purchase. | O4: High | P4: 9 | Q4: verified independent | R4: Phone / WhatsApp 02-544-5668 (WhatsApp link on official site) | S4: https://birmacoffee.com | T4: https://birmacoffee.com | U4: 2026-10-25 | V4: Not Contacted | W4: Phone confirmed on the official site (2026-10-25). Street number 20 from rest.co.il (https://www.rest.co.il/rest/80358238/) and Debbest; the official site gives no number. Founders named on own site and in Times of Israel FR (Aug 2023). No email published. | X4: היי מיכאל ודניאל, אני [השם שלך] מ-Perko. ראיתי מה בניתם בבירמה: קלייה קטנה, דלפק עם לקוחות קבועים שעוצרים בדרך לעבודה. בדיוק העסק שכרטיס חותמות נועד בשבילו. אנחנו מפתחים כרטיס נאמנות דיגיטלי משותף לעסקים בשכונה. במקום כרטיס נייר, הלקוח סורק קוד בקופה וצובר חותמות לפי הכללים שלכם, והכרטיס שלכם יושב באותה אפליקציה עם עוד עסקים מהרחוב. אנחנו בגישה מוקדמת ומחפשים כמה עסקים ראשונים שיעזרו לנו לבנות את זה נכון. ההצטרפות כרגע בחינם, בלי התחייבות. בא לכם 15 דקות שיחה השבוע? אשמח להגיע לדלפק. [השם שלך]
A5: קאלו | B5: Kalo Cafe & Market | C5: Café / deli | D5: Derech Beit Lehem | E5: 31 Derech Beit Lehem, Baka, Jerusalem | F5: 02-673-6365 | G5: kalocafe@gmail.com | H5: https://www.kalocafe.co.il/ | I5: https://www.instagram.com/kalocafejerusalem | J5: https://www.facebook.com/kalocafe/ | M5: Kosher neighbourhood café on the street since 1997/98 serving breakfasts, sandwiches, pastas and salads, plus deli and ready-made products sold online. | N5: A Baka institution with a large local base (800+ Google reviews per Wanderlog) and two purchase types, café visits and deli and ready-meal shopping. A shared card could carry its regulars to the other Derech Beit Lehem shops, and it already sells online, so it is used to digital tools. | O5: High | P5: 9 | Q5: verified independent | R5: Email kalocafe@gmail.com, or phone 02-673-6365 | S5: https://he.wikipedia.org/wiki/%D7%93%D7%A8%D7%9A_%D7%91%D7%99%D7%AA_%D7%9C%D7%97%D7%9D | T5: https://www.kalocafe.co.il/contact-us/ | U5: 2026-10-25 | V5: Not Contacted | W5: Email and phone confirmed on the official contact page (2026-10-25). Single location; company פרידה קאלו בע"מ. Owner not named publicly. Directory hours conflict, so check before visiting. | X5: שלום לצוות קאלו, אני [השם שלך] מ-Perko. קאלו הוא כבר שנים חלק מהשגרה של בקעה, גם בבית הקפה וגם במעדנייה, ונראה לי שיש לכם בדיוק את הקהל הקבוע שאנחנו בונים בשבילו. Perko הוא כרטיס נאמנות דיגיטלי משותף לעסקים בשכונה: הלקוח סורק קוד בקופה, צובר חותמות או נקודות לפי ההטבה שאתם מגדירים, ורואה באותה אפליקציה גם עסקים נוספים בדרך בית לחם. אנחנו בשלב גישה מוקדמת ומחפשים עסקים ראשונים שישפיעו על איך המוצר יעבוד בקופה. ההצטרפות כרגע בחינם ובלי התחייבות לתשלום. אשמח לדבר עם מי שאחראי אצלכם על הלקוחות, או לקפוץ ולהראות. למי כדאי לפנות? תודה, [השם שלך]
A6: טחנת הקפה | B6: The Coffee Mill | C6: Café / coffee roaster | D6: Emek Refaim | E6: 23 Emek Refaim St, German Colony, Jerusalem | F6: 02-566-1665 | G6: coffeemill99@gmail.com | H6: https://www.thecoffeemill.co.il/en | I6: https://www.instagram.com/thecoffeemillil | J6: https://www.facebook.com/coffeemill99 | K6: Leah Breslow; Avi Katz | L6: Owners since 2016 (Leah Breslow runs day-to-day operations) | M6: Family-owned neighbourhood café that has roasted its own coffee since 1996 and sells single-origin and blended beans. Kosher. | N6: Two repeat loops in one shop: the daily coffee and the bag of beans re-bought every few weeks. Owners are named on their own site, so the first conversation can go straight to the decision-makers, and its neighbours on Emek Refaim (bakeries, florists) are natural network partners. | O6: High | P6: 9 | Q6: verified independent | R6: Email coffeemill99@gmail.com, or phone 02-566-1665 | S6: https://www.thecoffeemill.co.il/en/about | T6: https://www.thecoffeemill.co.il/en/about | U6: 2026-10-25 | V6: Not Contacted | W6: Email and phone confirmed on the official About page (2026-10-25). Listed at no. 23 in The Jerusalem Guide German Colony feature (3 Jul 2026). Social URLs taken from the official site. Emek Refaim light-rail works may affect footfall in 2026. | X6: שלום לאה ואבי, אני [השם שלך] מ-Perko. טחנת הקפה היא מקום שאנשים חוזרים אליו כל בוקר, וגם קונים שוב את הפולים שלכם כל כמה שבועות. אנחנו בונים כרטיס נאמנות דיגיטלי משותף לעסקים בשכונה: הלקוח סורק קוד בקופה, צובר חותמות לפי הכללים שאתם קובעים, ורואה באותה אפליקציה גם כרטיסים של עסקים אחרים ברחוב. אנחנו בשלב גישה מוקדמת ומחפשים כמה עסקים ראשונים בעמק רפאים שיעזרו לנו לעצב את המוצר. ההצטרפות כרגע בחינם ובלי התחייבות לתשלום. אשמח ל-15 דקות שיחה או לקפץ אליכם לקפה ולהראות במה מדובר. מתי נוח לכם? תודה, [השם שלך]
A7: קאסה לביא | B7: Casa Lavi | C7: Café / bakery | D7: Derech Beit Lehem | E7: 41 Derech Beit Lehem, Baka, Jerusalem | F7: 058-429-6540 | H7: https://casalavi.webflow.io/ | I7: https://www.instagram.com/casalavicafe | K7: Meital Itzhak; Alfonso Itzhak | L7: Founders / owners (per official site) | M7: Specialty coffee shop opened in 2022 that roasts its own coffee and bakes healthy pastries on site without white sugar or flour. Mostly vegan, kosher. | N7: A young, owner-run café with a health-focused crowd of regulars who come back for coffee and pastries several times a week. Its founder-led brand suits an early-access pilot. | O7: High | P7: 8 | Q7: verified independent | R7: Instagram DM @casalavicafe, or phone 058-429-6540 | S7: https://casalavi.webflow.io/ | T7: https://www.rest.co.il/rest/80359561/ | U7: 2026-10-25 | V7: Not Contacted | W7: Official site (webflow) checked 2026-10-25: Instagram link present, no phone. Phones conflict across directories: rest.co.il 058-4296540, Google (via Wanderlog) 02-631-0295. Google reviews dated Dec 2025 and Jan 2026 per Wanderlog. casalavicafe.com did not load (TLS error). | X7: היי מיטל ואלפונסו, אני [השם שלך] מ-Perko. אהבתי את מה שבניתם בקאסה לביא: קלייה משלכם, מאפים בריאים, וקהל שחוזר כמה פעמים בשבוע. אנחנו מפתחים כרטיס נאמנות דיגיטלי משותף לעסקים בשכונה. הלקוח סורק קוד בקופה, צובר חותמות לפי הכללים שלכם, ורואה באותה אפליקציה גם עסקים שכנים בדרך בית לחם. אנחנו בגישה מוקדמת ומחפשים כמה עסקים ראשונים שיעזרו לנו לעצב את המוצר. ההצטרפות כרגע בחינם, בלי התחייבות. אשמח לקפוץ לקפה ולהראות בכמה דקות. מתי נוח לכם? [השם שלך]
A8: פרחי העמק | B8: Emek Flowers (Pirchei HaEmek) | C8: Florist | D8: Emek Refaim | E8: 43 Emek Refaim St, German Colony, Jerusalem | F8: 052-404-3365 | H8: https://emekflowers.co.il/ | M8: Flower shop and boutique in the German Colony offering bouquets and deliveries across Jerusalem. | N8: Friday flowers for Shabbat are a weekly ritual for many local households, so a 'buy 8 bouquets, get one free' card fits naturally. A florist also makes a good second stop for café customers on the same street. | O8: High | P8: 8 | Q8: appears independent | R8: Phone 052-404-3365 | S8: https://emekflowers.co.il/ | T8: https://emekflowers.co.il/ | U8: 2026-10-25 | V8: Not Contacted | W8: Phone confirmed on the official site (2026-10-25); site footer ©2026 with current hours (Sun-Thu 10-19, Fri 7-16). Owner not named. A Wolt listing was seen in search results only. | X8: שלום לצוות פרחי העמק, אני [השם שלך] מ-Perko. הרבה משפחות בשכונה קונות פרחים לשבת כל שבוע, וזה בדיוק סוג הקנייה החוזרת שאנחנו בונים בשבילו. Perko הוא כרטיס נאמנות דיגיטלי משותף לעסקים ברחוב: הלקוח סורק קוד בקופה וצובר חותמות לפי מה שאתם מחליטים, למשל זר תשיעי במתנה. באותה אפליקציה הוא רואה גם בתי קפה ועסקים אחרים בעמק רפאים. אנחנו בגישה מוקדמת ומחפשים עסקים ראשונים. ההצטרפות כרגע בחינם ובלי התחייבות לתשלום. אשמח לשיחה של 10 דקות או לקפוץ לחנות. מתי מתאים? [השם שלך]
A9: המקום של איציק | B9: Itzik's Place | C9: Café | D9: Derech Beit Lehem | E9: 33 Derech Beit Lehem, Baka, Jerusalem | F9: 02-672-0247 | J9: https://wolt.com/he/isr/jerusalem/venue/itziks-place | M9: Kosher dairy neighbourhood café (breakfasts, sandwiches, salads, pasta, desserts) that grew out of a local kiosk and has run in its current form since 2003. | N9: A kiosk-turned-café lives on daily regulars from the surrounding streets, and with no website or app of its own a ready-made digital card replaces paper with zero setup. Being two doors from Kalo and the deli at no. 33 makes it a natural cluster for the pilot. | O9: High | P9: 8 | Q9: appears independent | R9: Phone 02-672-0247 or visit in person | S9: https://www.rest.co.il/rest/80214546/ | T9: https://www.rest.co.il/rest/80214546/ | U9: 2026-10-25 | V9: Not Contacted | W9: Wolt listing live (open on 25 Oct 2026). A second number, +972-54-522-2843, appears on Wolt. History from Hebrew Wikipedia's Derech Beit Lehem article. No website or published email. | X9: היי, שלום לצוות של המקום של איציק, אני [השם שלך] מ-Perko. אתם מהמקומות שהשכונה חוזרת אליהם כל יום, עוד מימי הקיוסק. אנחנו בונים כרטיס נאמנות דיגיטלי משותף לעסקים בדרך בית לחם. בלי כרטיס נייר ובלי אפליקציה נפרדת: הלקוח סורק קוד בקופה, צובר חותמות לפי מה שתחליטו (למשל קפה עשירי חינם), ובאותה אפליקציה רואה גם עסקים שכנים. אנחנו בגישה מוקדמת ומחפשים כמה עסקים ראשונים ברחוב. ההצטרפות כרגע בחינם, בלי התחייבות, ואנחנו עושים את כל ההקמה. אפשר לקפוץ אליכם לכמה דקות בשעה שקטה ולהראות? מה הזמן הכי נוח? [השם שלך]
A10: ציגה – הגלידה של ציגה | B10: Tziga Ice Cream | C10: Ice cream / gelato | D10: Derech Beit Lehem | E10: 31 Derech Beit Lehem, Baka, Jerusalem | F10: 02-502-8374 | H10: https://tziga.co.il/ | J10: https://wolt.com/he/isr/jerusalem/restaurant/tziga-ice-cream | M10: Small family-run kosher gelateria making artisanal Italian-style gelato and sorbets, with many vegan flavours. | N10: Ice cream is an impulse treat bought by the same local families week after week, which makes 'every 8th scoop free' an easy offer. It shares a building with Kalo, so a customer could pick up stamps at both on one outing. | O10: High | P10: 8 | Q10: appears independent | R10: Phone 02-502-8374 | S10: https://tziga.co.il/ | T10: https://tziga.co.il/ | U10: 2026-10-25 | V10: Not Contacted | W10: Phone confirmed on the official site (2026-10-25). Live on Wolt. One search snippet mentioned further branches (HaNasi St, Herzl Blvd), but neither the official site nor a Mako article lists them, so independence is not fully confirmed. Seasonal demand (summer peak). | X10: שלום לצוות ציגה, אני [השם שלך] מ-Perko. גלידה היא בדיוק הדבר שמשפחות מהשכונה חוזרות אליו שוב ושוב, ולכן חשבנו עליכם. Perko הוא כרטיס נאמנות דיגיטלי משותף לעסקים בשכונה: הלקוח סורק קוד בקופה וצובר חותמות לפי ההטבה שאתם קובעים, למשל ״כל כדור שמיני עלינו״. הכרטיס שלכם יופיע באותה אפליקציה עם עסקים נוספים בדרך בית לחם. אנחנו בגישה מוקדמת ומחפשים עסקים ראשונים שיעזרו לנו לבנות את המוצר. ההצטרפות כרגע בחינם ובלי התחייבות לתשלום. אשמח לשיחה קצרה או לקפוץ אליכם. מתי נוח? תודה, [השם שלך]
A11: ברזאולה | B11: Bresaola | C11: Deli / tapas bar | D11: Derech Beit Lehem | E11: 27 Derech Beit Lehem, Baka, Jerusalem | F11: 02-673-5522 | J11: https://www.facebook.com/bresaola.jlm/ | M11: Kosher deli-bar making handmade Italian-style sausages and charcuterie, with tapas and hot sandwiches. | N11: A take-home charcuterie counter that also serves a sit-down bar is visited both for weekly shopping and for evenings out. Its very high rating suggests loyal fans whose visits a reward could make more frequent. | O11: Medium | P11: 7 | Q11: appears independent | R11: Phone 02-673-5522 | S11: https://wolt.com/he/isr/jerusalem/restaurant/bresaola | T11: https://www.d.co.il/80361096/30455/ | U11: 2026-10-25 | V11: Not Contacted | W11: Live on Wolt (rating 9.2; open 25 Oct 2026). The Facebook page is the 'website' listed on Wolt. An Instagram handle @bresaola.jlm was seen only in search results, so it is not included. The domain bresaola-jerusalem.com did not resolve. | X11: שלום לצוות ברזאולה, אני [השם שלך] מ-Perko. יש לכם קהל מעריצים אמיתי, ומגיעים אליכם גם לקניות הביתה וגם לערב בבר. אנחנו בונים כרטיס נאמנות דיגיטלי משותף לעסקים בשכונה: הלקוח סורק קוד בקופה וצובר חותמות לפי ההטבה שאתם קובעים, ובאותה אפליקציה רואה גם עסקים שכנים בדרך בית לחם. אנחנו בגישה מוקדמת ומחפשים עסקים ראשונים שיעזרו לנו לבנות את המוצר. ההצטרפות כרגע בחינם ובלי התחייבות לתשלום. אשמח לקפוץ אליכם לכמה דקות. מתי הכי שקט אצלכם? [השם שלך]
A12: הפרחים של ארז | B12: Erez Flowers (EreZer) | C12: Florist | D12: Emek Refaim | E12: 26 Emek Refaim St, German Colony, Jerusalem | F12: 02-533-6363 | G12: erezprachim@gmail.com | H12: https://erez-flowers.co.il/ | J12: https://wolt.com/en/isr/jerusalem/venue/erezer-emek-refaim | M12: Flower and gift shop offering arrangements with same-day delivery across Jerusalem. | N12: A flower shop where both walk-in Shabbat buyers and delivery customers buy again and again. With email published, it is one of the easiest prospects to reach in writing. | O12: High | P12: 7 | Q12: appears independent | R12: Email erezprachim@gmail.com, or phone 02-533-6363 | S12: https://erez-flowers.co.il/store/ | T12: https://erez-flowers.co.il/ | U12: 2026-10-25 | V12: Not Contacted | W12: Email and phone confirmed on the official site (2026-10-25). The Wolt URL suffix '-emek-refaim' might hint at other branches, but none was found. Two florists on Emek Refaim (with Emek Flowers) may compete, so pitch them separately. | X12: שלום לצוות הפרחים של ארז, אני [השם שלך] מ-Perko. יש לכם גם קונים שנכנסים לחנות לפני שבת וגם לקוחות משלוחים שחוזרים, וזה בדיוק הקהל שאנחנו בונים בשבילו. Perko הוא כרטיס נאמנות דיגיטלי משותף לעסקים בעמק רפאים: הלקוח סורק קוד בקופה וצובר חותמות לפי ההטבה שאתם מגדירים, ובאותה אפליקציה רואה גם עסקים נוספים ברחוב. אנחנו בשלב גישה מוקדמת ומחפשים עסקים ראשונים. ההצטרפות כרגע בחינם ובלי התחייבות לתשלום. אשמח לשיחה של 10 דקות. מתי נוח לכם? תודה, [השם שלך]
A13: פלורה – חנות פרחים | B13: Flora Flower Shop | C13: Florist | D13: Derech Beit Lehem | E13: 29 Derech Beit Lehem, Baka, Jerusalem | F13: 073-375-3310 | G13: info@floraflower.co.il | H13: https://www.floraflower.co.il/ | M13: Florist selling bouquets, plants, event arrangements and gift bundles, with Jerusalem-wide delivery and free pickup in store. | N13: Weekly Shabbat flowers plus holiday spikes (Sukkot, Rosh Hashana, Mother's Day) suit a stamp card well. It is a few doors from Kalo and Tziga, so customers can collect at several stops on one walk. | O13: High | P13: 7 | Q13: appears independent | R13: Email info@floraflower.co.il | S13: https://www.floraflower.co.il/ | T13: https://www.floraflower.co.il/ | U13: 2026-10-25 | V13: Not Contacted | W13: Email and phone confirmed on the official site (2026-10-25); Sukkot 2026 promotions live. Directories show other numbers (d.co.il 077-3164751), so use the official one. | X13: שלום לצוות פלורה, אני [השם שלך] מ-Perko. פרחים לשבת, ועוד שיאים בחגים, הם בדיוק סוג הקנייה החוזרת שאנחנו בונים בשבילו. Perko הוא כרטיס נאמנות דיגיטלי משותף לעסקים בשכונה: הלקוח סורק קוד בקופה וצובר חותמות לפי מה שאתם מחליטים, למשל זר תשיעי במתנה. באותה אפליקציה הוא רואה גם בתי קפה ועסקים שכנים בדרך בית לחם. אנחנו בשלב גישה מוקדמת ומחפשים כמה עסקים ראשונים. ההצטרפות כרגע בחינם ובלי התחייבות לתשלום. אשמח לשיחה קצרה או לקפוץ לחנות. מתי נוח לכם? תודה, [השם שלך]
A14: גראנד קפה | B14: Grand Cafe | C14: Café / restaurant | D14: Derech Beit Lehem | E14: 70 Derech Beit Lehem, Baka, Jerusalem | F14: 02-570-2702 | H14: https://www.grand-cafe.co.il/ | I14: https://www.instagram.com/grand.cafe_/ | J14: https://www.facebook.com/grandcafe70 | K14: Adi Talmor; Sarah Talmor | L14: Co-founder (business side); café manager (per The Jewish Link, Dec 2025) | M14: European-style kosher dairy café-restaurant opened in 2011, known for brunch and pastries. | N14: A popular brunch spot with neighbourhood regulars, where a reward such as a free pastry could move weekend-only diners to weekday visits. Its scale makes it an anchor partner that lends the network credibility. | O14: Medium | P14: 7 | Q14: verified independent | R14: Phone 02-570-2702 or WhatsApp +972-52-667-4624 (both on official site) | S14: https://jewishlink.news/a-jerusalem-restaurant-to-remember-in-baka-the-grand-cafe/ | T14: https://www.grand-cafe.co.il/ | U14: 2026-10-25 | V14: Not Contacted | W14: Phone, WhatsApp and Instagram confirmed on the official site (2026-10-25). Live on Wolt. No email published (events contact form only). | X14: שלום עדי ושרה, אני [השם שלך] מ-Perko. גראנד קפה הוא אחד המקומות שמגדירים את בקעה, עם קהל בראנץ' נאמן. אנחנו בונים כרטיס נאמנות דיגיטלי משותף לעסקים בשכונה: הלקוח סורק קוד בקופה וצובר חותמות או נקודות לפי ההטבה שאתם מגדירים, למשל מאפה עלינו בביקור באמצע השבוע. באותה אפליקציה הוא רואה גם עסקים נוספים בדרך בית לחם. אנחנו בגישה מוקדמת ומחפשים עסקים ראשונים שיעזרו לנו לבנות את זה. ההצטרפות כרגע בחינם ובלי התחייבות לתשלום. אשמח לפגישה קצרה בזמן שנוח לכם. מתי מתאים? תודה, [השם שלך]
A15: לה שרולה | B15: Le Charolais Deli & Butcher | C15: Butcher / deli | D15: Derech Beit Lehem | E15: 84 Derech Beit Lehem, Baka, Jerusalem | F15: 050-579-1350 | H15: https://lecharolais.co.il/ | J15: https://www.facebook.com/lecharolaisjerusalem/ | M15: Kosher boutique butcher and deli; it will grill a cut to order on site and also sells poultry, prepared foods and weekend French pastries. | N15: Households buy meat for Shabbat every week, and high-value baskets justify a meaningful reward. It is also a different kind of shop from the cafés, which widens what the shared network offers. | O15: High | P15: 7 | Q15: appears independent | R15: Phone / WhatsApp 050-579-1350 (official site) | S15: https://lecharolais.co.il/ | T15: https://lecharolais.co.il/ | U15: 2026-10-25 | V15: Not Contacted | W15: Phone confirmed on the official site (2026-10-25). Wolt lists 02-6444966. A Mazav article (Jun 2021) names three Jerusalem restaurateurs as owners who also run other restaurants: a single shop, but not a lone owner. Names left out because the source is from 2021. | X15: שלום לצוות לה שרולה, אני [השם שלך] מ-Perko. הרבה משפחות בשכונה קונות אצלכם בשר לשבת כל שבוע, וזה בדיוק סוג הלקוח הקבוע שאנחנו בונים בשבילו. Perko הוא כרטיס נאמנות דיגיטלי משותף לעסקים בשכונה: הלקוח סורק קוד בקופה וצובר נקודות לפי הכללים שלכם, והכרטיס שלכם יושב באותה אפליקציה עם עסקים נוספים בדרך בית לחם. אנחנו בגישה מוקדמת ומחפשים עסקים ראשונים. ההצטרפות כרגע בחינם ובלי התחייבות לתשלום. אשמח לשיחה קצרה עם מי שמנהל את החנות. מתי נוח? [השם שלך]
A16: לחם ועוד | B16: Lechem V'od (Bread and More) | C16: Bakery / café | D16: Emek Refaim | E16: 35 Emek Refaim St, German Colony, Jerusalem | F16: 02-624-4255 | M16: Gourmet kosher (mehadrin) bakery-café and deli selling artisan bread, cheesecake, macarons and imported cheeses, with an outdoor patio. | N16: Daily bread and weekly Shabbat baking make bakeries the strongest repeat-purchase category. Its deli counter adds bigger baskets, which justify a richer reward. | O16: High | P16: 7 | Q16: appears independent | R16: Phone 02-624-4255 or visit in person | S16: https://www.rest.co.il/rest/80209734/ | T16: https://www.rest.co.il/rest/80209734/ | U16: 2026-10-25 | V16: Not Contacted | W16: Score reduced because current operation is not firmly verified: rest.co.il updated Feb 2026 and listed in iTravelJerusalem, but no dated 2026 review was found. Confirm it is open before outreach. Shares no. 35 with Focaccia Moshava. | X16: שלום לצוות לחם ועוד, אני [השם שלך] מ-Perko. מאפייה היא המקום שאנשים חוזרים אליו הכי הרבה, ללחם של כל יום ולעוגות של שבת. אנחנו בונים כרטיס נאמנות דיגיטלי משותף לעסקים בעמק רפאים: הלקוח סורק קוד בקופה, צובר חותמות לפי ההטבה שאתם קובעים, ורואה באותה אפליקציה גם עסקים שכנים ברחוב. אנחנו בגישה מוקדמת ומחפשים עסקים ראשונים. ההצטרפות כרגע בחינם ובלי התחייבות לתשלום. אשמח לקפוץ ולהראות בכמה דקות. מתי מתאים? [השם שלך]
A17: בוכמן'ס דיינר | B17: Buchman's Diner | C17: Casual restaurant | D17: Emek Refaim | E17: 51 Emek Refaim St, German Colony, Jerusalem | F17: 073-730-9889 | J17: https://wolt.com/en/isr/jerusalem/restaurant/buchmans-diner | K17: Lior Sivan; Matan Sivan | L17: Owners (twin brothers), per The Jerusalem Post, Nov 2024 | M17: American-style kosher dairy diner serving burgers, pancakes, calzones and milkshakes. | N17: Families and teenagers come back for casual meals, so a 'free milkshake on the 6th visit' card is easy to explain. Owner-operators are named, and they run two other local pizza places, so a successful pilot could later spread across their venues. | O17: Medium | P17: 6 | Q17: appears independent | R17: Phone 073-730-9889 | S17: https://jpost.com/food-recipes/article-829474 | T17: https://jpost.com/food-recipes/article-829474 | U17: 2026-10-25 | V17: Not Contacted | W17: Small local family group (also runs two Buchman pizza places), not a chain. Wolt listing seen in search results. Kashrut wording differs between sources. No 2026-dated evidence found. | X17: היי ליאור ומתן, אני [השם שלך] מ-Perko. הדיינר שלכם הוא מקום שמשפחות ובני נוער חוזרים אליו, וזה בדיוק הקהל שכרטיס חותמות עובד אצלו הכי טוב. Perko הוא כרטיס נאמנות דיגיטלי משותף לעסקים בשכונה: הלקוח סורק קוד בקופה וצובר חותמות לפי ההטבה שאתם קובעים, למשל מילקשייק חינם בביקור השישי. באותה אפליקציה הוא רואה גם עסקים נוספים בעמק רפאים. אנחנו בגישה מוקדמת ומחפשים עסקים ראשונים. ההצטרפות כרגע בחינם ובלי התחייבות לתשלום, ואם זה יעבוד אפשר יהיה להרחיב גם למקומות הנוספים שלכם. אשמח לשיחה קצרה. מתי נוח? [השם שלך]
A18: קומקום – בית תה | B18: Kumkum Tea House | C18: Tea house / café | D18: Derech Beit Lehem | E18: 23 Derech Beit Lehem, Baka, Jerusalem | F18: 050-656-3334 | H18: https://kumkumteahouse.com/ | I18: https://www.instagram.com/kumkum.tea.house | K18: Elisheva Levy | L18: Owner (per Times of Israel, 16 Aug 2026) | M18: Kosher British-style tea room serving afternoon tea, homemade scones and loose-leaf teas in a garden, with a small teaware and gift shop. | N18: An owner-run, community-minded venue whose reward could be a free pot of tea or scones. The retail corner (loose-leaf tea refills) adds a repeat purchase, and the owner was profiled in Aug 2026, so she is active and reachable. | O18: Medium | P18: 6 | Q18: verified independent | R18: Phone / WhatsApp 050-656-3334 | S18: https://www.timesofisrael.com/elisheva-levy-jerusalems-fairy-godmother/ | T18: https://kumkumteahouse.com/ | U18: 2026-10-25 | V18: Not Contacted | W18: Phone and Instagram confirmed on the official site after rendering it (2026-10-25). Afternoon tea is more of an occasion than a daily visit. Hebrew Wikipedia names a different owner; the 2026 Times of Israel article was used instead. GoKosher lists another phone, 077-5373226. | X18: שלום אלישבע, אני [השם שלך] מ-Perko. קראתי עלייך ועל קומקום, ואהבתי את הבית הקטן והקהילתי שבנית בבקעה. אנחנו מפתחים כרטיס נאמנות דיגיטלי משותף לעסקים בשכונה: הלקוח סורק קוד בקופה וצובר חותמות לפי מה שתבחרי, למשל קנקן תה או סקונס במתנה, וגם קניות של תה עלים לבית נספרות. באותה אפליקציה הוא רואה גם עסקים שכנים בדרך בית לחם. אנחנו בגישה מוקדמת ומחפשים עסקים ראשונים. ההצטרפות כרגע בחינם ובלי התחייבות לתשלום. אשמח לבוא לתה ולהראות בכמה דקות. מתי נוח לך? [השם שלך]
A19: פוקצ'ה בר הכשרה במושבה | B19: Focaccia Moshava | C19: Restaurant / bakery | D19: Emek Refaim | E19: 35 Emek Refaim St, German Colony, Jerusalem | F19: 02-538-7182 | M19: Kosher Italian restaurant baking focaccia in a taboon oven, with a Friday pre-Shabbat focaccia market. | N19: The Friday focaccia market is a weekly pickup routine and a ready-made reason to reward repeat visits. Its corner-of-the-street visibility would also help the network. | O19: Medium | P19: 5 | Q19: uncertain | R19: Phone 02-538-7182 | S19: https://www.itraveljerusalem.com/rst/focaccia-moshava/ | T19: https://www.rest.co.il/restaurants/jerusalem/emek-refaim/ | U19: 2026-10-25 | V19: Not Contacted | W19: Kosher sibling of the downtown Focaccia Bar (Rabbi Akiva St): a local two-location brand, not a single independent shop. Listed in The Jerusalem Guide (3 Jul 2026). A website (m.focaccia.co) appears on iTravelJerusalem but was not verified, so it is left blank. | X19: שלום לצוות פוקצ'ה במושבה, אני [השם שלך] מ-Perko. שוק הפוקצ'ות שלכם בשישי הוא בדיוק הרגל שבועי שכדאי לתגמל. אנחנו בונים כרטיס נאמנות דיגיטלי משותף לעסקים בעמק רפאים: הלקוח סורק קוד בקופה וצובר חותמות לפי ההטבה שאתם קובעים, למשל פוקצ'ה עלינו בשישי העשירי. באותה אפליקציה הוא רואה גם עסקים שכנים ברחוב. אנחנו בגישה מוקדמת ומחפשים עסקים ראשונים. ההצטרפות כרגע בחינם ובלי התחייבות לתשלום. אשמח לדבר עם מי שמנהל את הסניף. מתי נוח? תודה, [השם שלך]
A20: פומפידו | B20: Pompidou Bistro & Bar | C20: Restaurant / bar | D20: Emek Refaim | E20: 27 Emek Refaim St, German Colony, Jerusalem | F20: 02-625-1111 | M20: Italian-leaning kosher dairy bistro and cocktail bar with balconies over Emek Refaim. | N20: Evening and date-night visits come less often, but a shared network could send café customers to it at night, and a reward such as a free dessert can win back lapsed diners. | O20: Medium | P20: 5 | Q20: appears independent | R20: Phone 02-625-1111 | S20: https://www.rest.co.il/rest/80164067/ | T20: https://www.rest.co.il/rest/80164067/ | U20: 2026-10-25 | V20: Not Contacted | W20: Listed in The Jerusalem Guide German Colony feature (3 Jul 2026). No official site or social profile found. The latest rest.co.il review is from 2023. | X20: שלום לצוות פומפידו, אני [השם שלך] מ-Perko. אנחנו בונים כרטיס נאמנות דיגיטלי משותף לעסקים בעמק רפאים: הלקוח סורק קוד בקופה וצובר נקודות לפי ההטבה שאתם קובעים, למשל קינוח עלינו בביקור הרביעי. היתרון בשבילכם הוא החיבור לעסקים השכנים: לקוחות שמכירים את הרחוב מבתי הקפה ביום יכולים לגלות אתכם בערב דרך אותה אפליקציה. אנחנו בגישה מוקדמת ומחפשים עסקים ראשונים. ההצטרפות כרגע בחינם ובלי התחייבות לתשלום. אשמח לדבר עם מי שמנהל את המקום. מתי אפשר לתפוס אתכם? תודה, [השם שלך]
A21: רנדבו | B21: Rendez-Vous | C21: Casual restaurant | D21: Derech Beit Lehem | E21: 110 Derech Beit Lehem, Jerusalem | F21: 074-726-8306 | M21: Kosher-mehadrin restaurant serving pizza, pasta and pastries. | N21: Pizza and pasta are frequent family takeaway orders that suit a simple stamp card. It sits at the southern (Talpiot) end of the street, so it would extend the network beyond central Baka. | O21: Medium | P21: 5 | Q21: appears independent | R21: Phone 074-726-8306 | S21: https://www.rest.co.il/rest/80195583/ | T21: https://www.rest.co.il/rest/80195583/ | U21: 2026-10-25 | V21: Not Contacted | W21: rest.co.il updated Jun 2026 with a user review dated 19 Aug 2025 (negative). Sources disagree on the cuisine label. The 074 number may be a directory routing number; confirm the direct line in person. Farther from the central cluster. | X21: שלום לצוות רנדבו, אני [השם שלך] מ-Perko. פיצה ופסטה הן הזמנות שמשפחות חוזרות אליהן שוב ושוב, וזה בדיוק המקום שבו כרטיס חותמות עובד. Perko הוא כרטיס נאמנות דיגיטלי משותף לעסקים בדרך בית לחם: הלקוח סורק קוד בקופה וצובר חותמות לפי ההטבה שאתם קובעים, ובאותה אפליקציה רואה גם עסקים נוספים ברחוב. אנחנו בגישה מוקדמת ומחפשים עסקים ראשונים. ההצטרפות כרגע בחינם ובלי התחייבות לתשלום. אשמח לשיחה קצרה עם מי שמנהל את המקום. מתי נוח? [השם שלך]
A22: ברברה שו מתנות | B22: Barbara Shaw Gifts | C22: Gift / Judaica boutique | D22: Emek Refaim | E22: 6 Emek Refaim St, German Colony, Jerusalem | F22: 02-579-9621 | G22: barbshaw@gmail.com | H22: https://www.barbarashawgifts.com/ | M22: Designer-led brand of modern Jewish and Israeli gifts made in Jerusalem: mugs, totes, aprons, T-shirts, baby wear and holiday items. | N22: Gift and holiday shopping comes in seasons rather than every week, but a quirky local brand would benefit from the network's foot traffic. It sits at the northern start of Emek Refaim, where people begin walking the street. | O22: Low | P22: 4 | Q22: appears independent | R22: Email barbshaw@gmail.com | S22: https://www.barbarashawgifts.com/contact-us/ | T22: https://www.barbarashawgifts.com/contact-us/ | U22: 2026-10-25 | V22: Not Contacted | W22: Email and phone confirmed on the official contact page (2026-10-25). Local brand with two of its own shops (Emek Refaim 6 and Shlomtzion St), not a chain. The contact page lists first names (Barbara, Boaz) without roles, so no contact person is recorded. No 2025-26 dated evidence found. | X22: שלום ברברה, אני [השם שלך] מ-Perko. אנחנו בונים כרטיס נאמנות דיגיטלי משותף לעסקים בעמק רפאים: הלקוח סורק קוד בקופה, צובר הטבות לפי הכללים של כל עסק, ורואה באותה אפליקציה את כל העסקים המשתתפים ברחוב. בשביל חנות מתנות היתרון העיקרי הוא החשיפה: לקוחות קבועים של בתי הקפה והמאפיות ברחוב יכולים לגלות אתכם, במיוחד לפני החגים. ההטבה יכולה להיות משהו קטן, כמו עטיפת מתנה או הנחה לקנייה הבאה. אנחנו בגישה מוקדמת. ההצטרפות כרגע בחינם ובלי התחייבות לתשלום. אשמח לשמוע אם זה מעניין אותך. תודה, [השם שלך]
A23: סתיו תכשיטים | B23: Stav Jewelry | C23: Jewelry / gift boutique | D23: Emek Refaim | E23: 40 Emek Refaim St, German Colony, Jerusalem | F23: 02-563-7059 | G23: stavjewelry@gmail.com | H23: http://www.stavjewelry.com/ | I23: https://www.instagram.com/stav.jewelry | J23: https://www.facebook.com/stavjewelry | K23: Dalia Stav; Eyal Stav | L23: Founders / owners (designer couple) | M23: Jewelry designed and handmade in the shop's own workshop, in gold, silver and stones, since 1996. | N23: Few repeat purchases, but a long-standing, owner-run gift shop that would benefit from the network's discovery: café regulars finding a local gift shop. Its reward would be a higher-value gesture (e.g. a free repair or engraving) rather than stamps. | O23: Low | P23: 4 | Q23: verified independent | R23: Email stavjewelry@gmail.com | S23: http://www.stavjewelry.com/ | T23: http://www.stavjewelry.com/ | U23: 2026-10-25 | V23: Not Contacted | W23: Email and phone confirmed on the official site (2026-10-25); footer © 2026. Low purchase frequency, so better as a later-phase partner than a pilot anchor. | X23: שלום דליה ואייל, אני [השם שלך] מ-Perko. סתיו תכשיטים הוא מהעסקים הוותיקים והמיוחדים בעמק רפאים, וזה בדיוק סוג המקום שאנחנו רוצים שאנשים מהשכונה יגלו. אנחנו בונים כרטיס נאמנות דיגיטלי משותף לעסקים ברחוב. אצלכם זה לא יהיה כרטיס חותמות רגיל: אפשר להגדיר הטבה שמתאימה לתכשיטים, כמו ניקוי, תיקון או חריטה במתנה, ולהגיע ללקוחות של בתי הקפה והחנויות השכנות באותה אפליקציה. אנחנו בגישה מוקדמת. ההצטרפות כרגע בחינם ובלי התחייבות לתשלום. אשמח לשמוע אם זה מעניין אתכם, ולקפוץ לשיחה קצרה. תודה, [השם שלך]

Sheet Summary
A1: Perko - Prospect Summary
A2: Counts are formulas over the Prospects sheet, so they update when rows are edited.
A4: Totals
A5: Businesses in the list | B5: =COUNTA(Prospects!$B$4:$B$23)
A7: By street
A8: Derech Beit Lehem | B8: =COUNTIF(Prospects!$D$4:$D$23,"Derech Beit Lehem") | C8: =B8/20
A9: Emek Refaim | B9: =COUNTIF(Prospects!$D$4:$D$23,"Emek Refaim") | C9: =B9/20
A11: By business category
A12: Florist | B12: =COUNTIF(Prospects!$C$4:$C$23,"Florist") | C12: =B12/20
A13: Café / coffee roaster | B13: =COUNTIF(Prospects!$C$4:$C$23,"Café / coffee roaster") | C13: =B13/20
A14: Casual restaurant | B14: =COUNTIF(Prospects!$C$4:$C$23,"Casual restaurant") | C14: =B14/20
A15: Café / deli | B15: =COUNTIF(Prospects!$C$4:$C$23,"Café / deli") | C15: =B15/20
A16: Café / bakery | B16: =COUNTIF(Prospects!$C$4:$C$23,"Café / bakery") | C16: =B16/20
A17: Café | B17: =COUNTIF(Prospects!$C$4:$C$23,"Café") | C17: =B17/20
A18: Ice cream / gelato | B18: =COUNTIF(Prospects!$C$4:$C$23,"Ice cream / gelato") | C18: =B18/20
A19: Deli / tapas bar | B19: =COUNTIF(Prospects!$C$4:$C$23,"Deli / tapas bar") | C19: =B19/20
A20: Café / restaurant | B20: =COUNTIF(Prospects!$C$4:$C$23,"Café / restaurant") | C20: =B20/20
A21: Butcher / deli | B21: =COUNTIF(Prospects!$C$4:$C$23,"Butcher / deli") | C21: =B21/20
A22: Bakery / café | B22: =COUNTIF(Prospects!$C$4:$C$23,"Bakery / café") | C22: =B22/20
A23: Tea house / café | B23: =COUNTIF(Prospects!$C$4:$C$23,"Tea house / café") | C23: =B23/20
A24: Restaurant / bakery | B24: =COUNTIF(Prospects!$C$4:$C$23,"Restaurant / bakery") | C24: =B24/20
A25: Restaurant / bar | B25: =COUNTIF(Prospects!$C$4:$C$23,"Restaurant / bar") | C25: =B25/20
A26: Gift / Judaica boutique | B26: =COUNTIF(Prospects!$C$4:$C$23,"Gift / Judaica boutique") | C26: =B26/20
A27: Jewelry / gift boutique | B27: =COUNTIF(Prospects!$C$4:$C$23,"Jewelry / gift boutique") | C27: =B27/20
A29: By Perko fit score
A30: High fit (8-10) | B30: =COUNTIFS(Prospects!$P$4:$P$23,">=8",Prospects!$P$4:$P$23,"<=10") | C30: =B30/20
A31: Medium fit (6-7) | B31: =COUNTIFS(Prospects!$P$4:$P$23,">=6",Prospects!$P$4:$P$23,"<=7") | C31: =B31/20
A32: Lower fit (1-5) | B32: =COUNTIFS(Prospects!$P$4:$P$23,">=1",Prospects!$P$4:$P$23,"<=5") | C32: =B32/20
A33: Average fit score | B33: =ROUND(AVERAGE(Prospects!$P$4:$P$23),1)
A35: By repeat-customer potential
A36: High | B36: =COUNTIF(Prospects!$O$4:$O$23,"High") | C36: =B36/20
A37: Medium | B37: =COUNTIF(Prospects!$O$4:$O$23,"Medium") | C37: =B37/20
A38: Low | B38: =COUNTIF(Prospects!$O$4:$O$23,"Low") | C38: =B38/20
A40: Contact-information completeness
A41: Public phone listed (official site, directory or press) | B41: =COUNTA(Prospects!$F$4:$F$23) | C41: =B41/20
A42: Public email published by the business | B42: =COUNTA(Prospects!$G$4:$G$23) | C42: =B42/20
A43: Official website | B43: =COUNTA(Prospects!$H$4:$H$23) | C43: =B43/20
A44: Instagram profile | B44: =COUNTA(Prospects!$I$4:$I$23) | C44: =B44/20
A45: Other social profile | B45: =COUNTA(Prospects!$J$4:$J$23) | C45: =B45/20
A46: Named contact person | B46: =COUNTA(Prospects!$K$4:$K$23) | C46: =B46/20
...
